Workbook

Sheet Resumen
A1: Plan de Proyecto – Sistema de Monitoreo CIP en Tiempo Real (MVP)
A2: Plataforma: Firebase (GCP) – Cloud Functions, Authentication, Firestore/Realtime Database, Hosting
A4: Datos generales del proyecto
A5: Fecha de inicio del MVP | B5: 46258
A6: Fecha de entrega del MVP (demo cliente) | B6: 46360
A7: Duración total | B7: 14.5 semanas (~3.3 meses) — comprimida desde el plazo original al 18-12
A8: Metodología | B8: Ágil (Scrum) – Sprints de 2 semanas
A9: N° de sprints | B9: 7 sprints de 2 semanas + 1 semana final de cierre/demo (antes eran 8 sprints + cierre)
A10: Equipo | B10: 4 desarrolladores polifuncionales + 1 técnico de hardware/maqueta
A11: Clientes objetivo del monitoreo | B11: Plantas de alimentos (ej. Soprole, Colun) que usan procesos de limpieza CIP
A12: Variables a monitorear | B12: Consumo de químicos, consumo de agua, temperatura, conductividad, pH y otras variables de sensores
A13: ⚠ Riesgo de cronograma | B13: Se mantiene el alcance completo (incluido ML predictivo) pese a tener una sprint menos; la semana de cierre ya no es un colchón real — ver pestaña Riesgos
A15: Alcance del MVP
A16: • | B16: Maqueta funcional (banco de pruebas) con sensores reales conectados: temperatura, conductividad, pH, flujo/consumo de agua y químicos.
A17: • | B17: Pipeline de ingesta de datos: sensores/gateway → Cloud Functions → Firestore/Realtime Database.
A18: • | B18: Aplicación web propia (sin herramientas externas tipo Power BI) para visualizar datos en tiempo real.
A19: • | B19: Autenticación de usuarios (Firebase Authentication) con al menos un rol de cliente y uno interno/admin.
A20: • | B20: Panel de consumo de químicos y agua provistos por la empresa, con datos históricos básicos.
A21: • | B21: Análisis predictivo con Machine Learning clásico (regresión / series de tiempo tipo ARIMA o Prophet / detección de anomalías) sobre consumo de químicos/agua y variables críticas (pH, temperatura, conductividad), entrenado con datos simulados desde el inicio y recalibrado con datos reales de la maqueta a medida que se acumulan.
A22: • | B22: Despliegue en un proyecto Firebase/GCP listo para demo ante el cliente el 04-12-2026.
A24: Fuera de alcance (post-MVP)
A25: • | B25: Reportes avanzados / exportables automatizados y alertas por correo o SMS.
A26: • | B26: Múltiples plantas/clientes en simultáneo (multi-tenant completo).
A27: • | B27: Deep learning (redes neuronales / LSTM) para el predictivo — el ML clásico entrenado con datos simulados y recalibrado con datos reales es lo que entra al MVP; modelos más sofisticados quedan como evolución post-MVP, cuando existan meses de datos reales.

Sheet Avance
A1: Avance del proyecto: plan vs. real (calculado desde 'Backlog por Sprint')
A2: Fecha de corte | B2: 46313 | C2: ← cambiar esta fecha recalcula atrasos y 'días ejecutados' en todo el libro
A3: Sprint | B3: Total | C3: Hecho | D3: En proceso | E3: Por hacer | F3: % hecho (n° actividades) | G3: Días hechos | H3: Días totales
A4: Sprint 1 | B4: =COUNTIF('Backlog por Sprint'!$A$2:$A$71,A4) | C4: =COUNTIFS('Backlog por Sprint'!$A$2:$A$71,$A4,'Backlog por Sprint'!$G$2:$G$71,"Hecho") | D4: =COUNTIFS('Backlog por Sprint'!$A$2:$A$71,$A4,'Backlog por Sprint'!$G$2:$G$71,"En proceso") | E4: =COUNTIFS('Backlog por Sprint'!$A$2:$A$71,$A4,'Backlog por Sprint'!$G$2:$G$71,"Por hacer") | F4: =IF(B4=0,0,C4/B4) | G4: =SUMIFS('Backlog por Sprint'!$E$2:$E$71,'Backlog por Sprint'!$A$2:$A$71,$A4,'Backlog por Sprint'!$G$2:$G$71,"Hecho") | H4: =SUMIF('Backlog por Sprint'!$A$2:$A$71,$A4,'Backlog por Sprint'!$E$2:$E$71)
A5: Sprint 2 | B5: =COUNTIF('Backlog por Sprint'!$A$2:$A$71,A5) | C5: =COUNTIFS('Backlog por Sprint'!$A$2:$A$71,$A5,'Backlog por Sprint'!$G$2:$G$71,"Hecho") | D5: =COUNTIFS('Backlog por Sprint'!$A$2:$A$71,$A5,'Backlog por Sprint'!$G$2:$G$71,"En proceso") | E5: =COUNTIFS('Backlog por Sprint'!$A$2:$A$71,$A5,'Backlog por Sprint'!$G$2:$G$71,"Por hacer") | F5: =IF(B5=0,0,C5/B5) | G5: =SUMIFS('Backlog por Sprint'!$E$2:$E$71,'Backlog por Sprint'!$A$2:$A$71,$A5,'Backlog por Sprint'!$G$2:$G$71,"Hecho") | H5: =SUMIF('Backlog por Sprint'!$A$2:$A$71,$A5,'Backlog por Sprint'!$E$2:$E$71)
A6: Sprint 3 | B6: =COUNTIF('Backlog por Sprint'!$A$2:$A$71,A6) | C6: =COUNTIFS('Backlog por Sprint'!$A$2:$A$71,$A6,'Backlog por Sprint'!$G$2:$G$71,"Hecho") | D6: =COUNTIFS('Backlog por Sprint'!$A$2:$A$71,$A6,'Backlog por Sprint'!$G$2:$G$71,"En proceso") | E6: =COUNTIFS('Backlog por Sprint'!$A$2:$A$71,$A6,'Backlog por Sprint'!$G$2:$G$71,"Por hacer") | F6: =IF(B6=0,0,C6/B6) | G6: =SUMIFS('Backlog por Sprint'!$E$2:$E$71,'Backlog por Sprint'!$A$2:$A$71,$A6,'Backlog por Sprint'!$G$2:$G$71,"Hecho") | H6: =SUMIF('Backlog por Sprint'!$A$2:$A$71,$A6,'Backlog por Sprint'!$E$2:$E$71)
A7: Sprint 4 | B7: =COUNTIF('Backlog por Sprint'!$A$2:$A$71,A7) | C7: =COUNTIFS('Backlog por Sprint'!$A$2:$A$71,$A7,'Backlog por Sprint'!$G$2:$G$71,"Hecho") | D7: =COUNTIFS('Backlog por Sprint'!$A$2:$A$71,$A7,'Backlog por Sprint'!$G$2:$G$71,"En proceso") | E7: =COUNTIFS('Backlog por Sprint'!$A$2:$A$71,$A7,'Backlog por Sprint'!$G$2:$G$71,"Por hacer") | F7: =IF(B7=0,0,C7/B7) | G7: =SUMIFS('Backlog por Sprint'!$E$2:$E$71,'Backlog por Sprint'!$A$2:$A$71,$A7,'Backlog por Sprint'!$G$2:$G$71,"Hecho") | H7: =SUMIF('Backlog por Sprint'!$A$2:$A$71,$A7,'Backlog por Sprint'!$E$2:$E$71)
A8: Sprint 5 | B8: =COUNTIF('Backlog por Sprint'!$A$2:$A$71,A8) | C8: =COUNTIFS('Backlog por Sprint'!$A$2:$A$71,$A8,'Backlog por Sprint'!$G$2:$G$71,"Hecho") | D8: =COUNTIFS('Backlog por Sprint'!$A$2:$A$71,$A8,'Backlog por Sprint'!$G$2:$G$71,"En proceso") | E8: =COUNTIFS('Backlog por Sprint'!$A$2:$A$71,$A8,'Backlog por Sprint'!$G$2:$G$71,"Por hacer") | F8: =IF(B8=0,0,C8/B8) | G8: =SUMIFS('Backlog por Sprint'!$E$2:$E$71,'Backlog por Sprint'!$A$2:$A$71,$A8,'Backlog por Sprint'!$G$2:$G$71,"Hecho") | H8: =SUMIF('Backlog por Sprint'!$A$2:$A$71,$A8,'Backlog por Sprint'!$E$2:$E$71)
A9: Sprint 6 | B9: =COUNTIF('Backlog por Sprint'!$A$2:$A$71,A9) | C9: =COUNTIFS('Backlog por Sprint'!$A$2:$A$71,$A9,'Backlog por Sprint'!$G$2:$G$71,"Hecho") | D9: =COUNTIFS('Backlog por Sprint'!$A$2:$A$71,$A9,'Backlog por Sprint'!$G$2:$G$71,"En proceso") | E9: =COUNTIFS('Backlog por Sprint'!$A$2:$A$71,$A9,'Backlog por Sprint'!$G$2:$G$71,"Por hacer") | F9: =IF(B9=0,0,C9/B9) | G9: =SUMIFS('Backlog por Sprint'!$E$2:$E$71,'Backlog por Sprint'!$A$2:$A$71,$A9,'Backlog por Sprint'!$G$2:$G$71,"Hecho") | H9: =SUMIF('Backlog por Sprint'!$A$2:$A$71,$A9,'Backlog por Sprint'!$E$2:$E$71)
A10: Sprint 7 | B10: =COUNTIF('Backlog por Sprint'!$A$2:$A$71,A10) | C10: =COUNTIFS('Backlog por Sprint'!$A$2:$A$71,$A10,'Backlog por Sprint'!$G$2:$G$71,"Hecho") | D10: =COUNTIFS('Backlog por Sprint'!$A$2:$A$71,$A10,'Backlog por Sprint'!$G$2:$G$71,"En proceso") | E10: =COUNTIFS('Backlog por Sprint'!$A$2:$A$71,$A10,'Backlog por Sprint'!$G$2:$G$71,"Por hacer") | F10: =IF(B10=0,0,C10/B10) | G10: =SUMIFS('Backlog por Sprint'!$E$2:$E$71,'Backlog por Sprint'!$A$2:$A$71,$A10,'Backlog por Sprint'!$G$2:$G$71,"Hecho") | H10: =SUMIF('Backlog por Sprint'!$A$2:$A$71,$A10,'Backlog por Sprint'!$E$2:$E$71)
A11: Cierre | B11: =COUNTIF('Backlog por Sprint'!$A$2:$A$71,A11) | C11: =COUNTIFS('Backlog por Sprint'!$A$2:$A$71,$A11,'Backlog por Sprint'!$G$2:$G$71,"Hecho") | D11: =COUNTIFS('Backlog por Sprint'!$A$2:$A$71,$A11,'Backlog por Sprint'!$G$2:$G$71,"En proceso") | E11: =COUNTIFS('Backlog por Sprint'!$A$2:$A$71,$A11,'Backlog por Sprint'!$G$2:$G$71,"Por hacer") | F11: =IF(B11=0,0,C11/B11) | G11: =SUMIFS('Backlog por Sprint'!$E$2:$E$71,'Backlog por Sprint'!$A$2:$A$71,$A11,'Backlog por Sprint'!$G$2:$G$71,"Hecho") | H11: =SUMIF('Backlog por Sprint'!$A$2:$A$71,$A11,'Backlog por Sprint'!$E$2:$E$71)
A12: Total | B12: =SUM(B4:B11) | C12: =SUM(C4:C11) | D12: =SUM(D4:D11) | E12: =SUM(E4:E11) | F12: =IF(B12=0,0,C12/B12) | G12: =SUM(G4:G11) | H12: =SUM(H4:H11)
A14: Por origen
A15: Plan original | B15: =COUNTIF('Backlog por Sprint'!$I$2:$I$71,"Plan original") | C15: =COUNTIFS('Backlog por Sprint'!$I$2:$I$71,"Plan original",'Backlog por Sprint'!$G$2:$G$71,"Hecho") | D15: =COUNTIFS('Backlog por Sprint'!$I$2:$I$71,"Plan original",'Backlog por Sprint'!$G$2:$G$71,"En proceso") | E15: =COUNTIFS('Backlog por Sprint'!$I$2:$I$71,"Plan original",'Backlog por Sprint'!$G$2:$G$71,"Por hacer") | F15: =IF(B15=0,0,C15/B15) | G15: =SUMIFS('Backlog por Sprint'!$E$2:$E$71,'Backlog por Sprint'!$I$2:$I$71,"Plan original",'Backlog por Sprint'!$G$2:$G$71,"Hecho") | H15: =SUMIF('Backlog por Sprint'!$I$2:$I$71,"Plan original",'Backlog por Sprint'!$E$2:$E$71)
A16: Agregadas (no planificadas) | B16: =COUNTIF('Backlog por Sprint'!$I$2:$I$71,"Agregada*") | C16: =COUNTIFS('Backlog por Sprint'!$I$2:$I$71,"Agregada*",'Backlog por Sprint'!$G$2:$G$71,"Hecho") | D16: =COUNTIFS('Backlog por Sprint'!$I$2:$I$71,"Agregada*",'Backlog por Sprint'!$G$2:$G$71,"En proceso") | E16: =COUNTIFS('Backlog por Sprint'!$I$2:$I$71,"Agregada*",'Backlog por Sprint'!$G$2:$G$71,"Por hacer") | F16: =IF(B16=0,0,C16/B16) | G16: =SUMIFS('Backlog por Sprint'!$E$2:$E$71,'Backlog por Sprint'!$I$2:$I$71,"Agregada*",'Backlog por Sprint'!$G$2:$G$71,"Hecho") | H16: =SUMIF('Backlog por Sprint'!$I$2:$I$71,"Agregada*",'Backlog por Sprint'!$E$2:$E$71)
A18: Notas:
A19: • Estados actualizados según evidencia en el repositorio (ramas feature/HL, CR, main) y lo informado por el equipo el 18-10-2026.
A20: • La maqueta física y la recepción de sensores no se pueden verificar en git: se registran según lo indicado por el equipo.
A21: • Días de las actividades agregadas: estimación retroactiva (ver nota al final de 'Backlog por Sprint').
A22: • Fuentes de estados: Aplicación/stormcip/SPRINT3.md, Base de datos/PENDIENTES-DASHBOARD.md y el historial de commits.
A24: Contraste de plazos: actividades del plan original
A25: Sprint | B25: Fin plan | C25: Actividades | D25: Hechas a tiempo | E25: Hechas con atraso | F25: Hechas sin fecha | G25: Pendientes atrasadas | H25: Pendientes en plazo | I25: Mayor atraso (días) | J25: Mayor atraso (semanas)
A26: Sprint 1 | B26: =INDEX('Roadmap Sprints'!$C$2:$C$9,MATCH(IF(A26="Cierre","Semana de cierre",A26),'Roadmap Sprints'!$A$2:$A$9,0)) | C26: =COUNTIFS('Backlog por Sprint'!$A$2:$A$71,$A26,'Backlog por Sprint'!$I$2:$I$71,"Plan original") | D26: =COUNTIFS('Backlog por Sprint'!$A$2:$A$71,$A26,'Backlog por Sprint'!$Q$2:$Q$71,"Hecha a tiempo") | E26: =COUNTIFS('Backlog por Sprint'!$A$2:$A$71,$A26,'Backlog por Sprint'!$Q$2:$Q$71,"Hecha con atraso") | F26: =COUNTIFS('Backlog por Sprint'!$A$2:$A$71,$A26,'Backlog por Sprint'!$Q$2:$Q$71,"Hecha (sin fecha)") | G26: =COUNTIFS('Backlog por Sprint'!$A$2:$A$71,$A26,'Backlog por Sprint'!$Q$2:$Q$71,"Pendiente atrasada") | H26: =COUNTIFS('Backlog por Sprint'!$A$2:$A$71,$A26,'Backlog por Sprint'!$Q$2:$Q$71,"Pendiente en plazo") | I26: =MAX(0,_xlfn.MAXIFS('Backlog por Sprint'!$O$2:$O$71,'Backlog por Sprint'!$A$2:$A$71,$A26,'Backlog por Sprint'!$I$2:$I$71,"Plan original")) | J26: =ROUND(I26/7,1)
A27: Sprint 2 | B27: =INDEX('Roadmap Sprints'!$C$2:$C$9,MATCH(IF(A27="Cierre","Semana de cierre",A27),'Roadmap Sprints'!$A$2:$A$9,0)) | C27: =COUNTIFS('Backlog por Sprint'!$A$2:$A$71,$A27,'Backlog por Sprint'!$I$2:$I$71,"Plan original") | D27: =COUNTIFS('Backlog por Sprint'!$A$2:$A$71,$A27,'Backlog por Sprint'!$Q$2:$Q$71,"Hecha a tiempo") | E27: =COUNTIFS('Backlog por Sprint'!$A$2:$A$71,$A27,'Backlog por Sprint'!$Q$2:$Q$71,"Hecha con atraso") | F27: =COUNTIFS('Backlog por Sprint'!$A$2:$A$71,$A27,'Backlog por Sprint'!$Q$2:$Q$71,"Hecha (sin fecha)") | G27: =COUNTIFS('Backlog por Sprint'!$A$2:$A$71,$A27,'Backlog por Sprint'!$Q$2:$Q$71,"Pendiente atrasada") | H27: =COUNTIFS('Backlog por Sprint'!$A$2:$A$71,$A27,'Backlog por Sprint'!$Q$2:$Q$71,"Pendiente en plazo") | I27: =MAX(0,_xlfn.MAXIFS('Backlog por Sprint'!$O$2:$O$71,'Backlog por Sprint'!$A$2:$A$71,$A27,'Backlog por Sprint'!$I$2:$I$71,"Plan original")) | J27: =ROUND(I27/7,1)
A28: Sprint 3 | B28: =INDEX('Roadmap Sprints'!$C$2:$C$9,MATCH(IF(A28="Cierre","Semana de cierre",A28),'Roadmap Sprints'!$A$2:$A$9,0)) | C28: =COUNTIFS('Backlog por Sprint'!$A$2:$A$71,$A28,'Backlog por Sprint'!$I$2:$I$71,"Plan original") | D28: =COUNTIFS('Backlog por Sprint'!$A$2:$A$71,$A28,'Backlog por Sprint'!$Q$2:$Q$71,"Hecha a tiempo") | E28: =COUNTIFS('Backlog por Sprint'!$A$2:$A$71,$A28,'Backlog por Sprint'!$Q$2:$Q$71,"Hecha con atraso") | F28: =COUNTIFS('Backlog por Sprint'!$A$2:$A$71,$A28,'Backlog por Sprint'!$Q$2:$Q$71,"Hecha (sin fecha)") | G28: =COUNTIFS('Backlog por Sprint'!$A$2:$A$71,$A28,'Backlog por Sprint'!$Q$2:$Q$71,"Pendiente atrasada") | H28: =COUNTIFS('Backlog por Sprint'!$A$2:$A$71,$A28,'Backlog por Sprint'!$Q$2:$Q$71,"Pendiente en plazo") | I28: =MAX(0,_xlfn.MAXIFS('Backlog por Sprint'!$O$2:$O$71,'Backlog por Sprint'!$A$2:$A$71,$A28,'Backlog por Sprint'!$I$2:$I$71,"Plan original")) | J28: =ROUND(I28/7,1)
A29: Sprint 4 | B29: =INDEX('Roadmap Sprints'!$C$2:$C$9,MATCH(IF(A29="Cierre","Semana de cierre",A29),'Roadmap Sprints'!$A$2:$A$9,0)) | C29: =COUNTIFS('Backlog por Sprint'!$A$2:$A$71,$A29,'Backlog por Sprint'!$I$2:$I$71,"Plan original") | D29: =COUNTIFS('Backlog por Sprint'!$A$2:$A$71,$A29,'Backlog por Sprint'!$Q$2:$Q$71,"Hecha a tiempo") | E29: =COUNTIFS('Backlog por Sprint'!$A$2:$A$71,$A29,'Backlog por Sprint'!$Q$2:$Q$71,"Hecha con atraso") | F29: =COUNTIFS('Backlog por Sprint'!$A$2:$A$71,$A29,'Backlog por Sprint'!$Q$2:$Q$71,"Hecha (sin fecha)") | G29: =COUNTIFS('Backlog por Sprint'!$A$2:$A$71,$A29,'Backlog por Sprint'!$Q$2:$Q$71,"Pendiente atrasada") | H29: =COUNTIFS('Backlog por Sprint'!$A$2:$A$71,$A29,'Backlog por Sprint'!$Q$2:$Q$71,"Pendiente en plazo") | I29: =MAX(0,_xlfn.MAXIFS('Backlog por Sprint'!$O$2:$O$71,'Backlog por Sprint'!$A$2:$A$71,$A29,'Backlog por Sprint'!$I$2:$I$71,"Plan original")) | J29: =ROUND(I29/7,1)
A30: Sprint 5 | B30: =INDEX('Roadmap Sprints'!$C$2:$C$9,MATCH(IF(A30="Cierre","Semana de cierre",A30),'Roadmap Sprints'!$A$2:$A$9,0)) | C30: =COUNTIFS('Backlog por Sprint'!$A$2:$A$71,$A30,'Backlog por Sprint'!$I$2:$I$71,"Plan original") | D30: =COUNTIFS('Backlog por Sprint'!$A$2:$A$71,$A30,'Backlog por Sprint'!$Q$2:$Q$71,"Hecha a tiempo") | E30: =COUNTIFS('Backlog por Sprint'!$A$2:$A$71,$A30,'Backlog por Sprint'!$Q$2:$Q$71,"Hecha con atraso") | F30: =COUNTIFS('Backlog por Sprint'!$A$2:$A$71,$A30,'Backlog por Sprint'!$Q$2:$Q$71,"Hecha (sin fecha)") | G30: =COUNTIFS('Backlog por Sprint'!$A$2:$A$71,$A30,'Backlog por Sprint'!$Q$2:$Q$71,"Pendiente atrasada") | H30: =COUNTIFS('Backlog por Sprint'!$A$2:$A$71,$A30,'Backlog por Sprint'!$Q$2:$Q$71,"Pendiente en plazo") | I30: =MAX(0,_xlfn.MAXIFS('Backlog por Sprint'!$O$2:$O$71,'Backlog por Sprint'!$A$2:$A$71,$A30,'Backlog por Sprint'!$I$2:$I$71,"Plan original")) | J30: =ROUND(I30/7,1)
A31: Sprint 6 | B31: =INDEX('Roadmap Sprints'!$C$2:$C$9,MATCH(IF(A31="Cierre","Semana de cierre",A31),'Roadmap Sprints'!$A$2:$A$9,0)) | C31: =COUNTIFS('Backlog por Sprint'!$A$2:$A$71,$A31,'Backlog por Sprint'!$I$2:$I$71,"Plan original") | D31: =COUNTIFS('Backlog por Sprint'!$A$2:$A$71,$A31,'Backlog por Sprint'!$Q$2:$Q$71,"Hecha a tiempo") | E31: =COUNTIFS('Backlog por Sprint'!$A$2:$A$71,$A31,'Backlog por Sprint'!$Q$2:$Q$71,"Hecha con atraso") | F31: =COUNTIFS('Backlog por Sprint'!$A$2:$A$71,$A31,'Backlog por Sprint'!$Q$2:$Q$71,"Hecha (sin fecha)") | G31: =COUNTIFS('Backlog por Sprint'!$A$2:$A$71,$A31,'Backlog por Sprint'!$Q$2:$Q$71,"Pendiente atrasada") | H31: =COUNTIFS('Backlog por Sprint'!$A$2:$A$71,$A31,'Backlog por Sprint'!$Q$2:$Q$71,"Pendiente en plazo") | I31: =MAX(0,_xlfn.MAXIFS('Backlog por Sprint'!$O$2:$O$71,'Backlog por Sprint'!$A$2:$A$71,$A31,'Backlog por Sprint'!$I$2:$I$71,"Plan original")) | J31: =ROUND(I31/7,1)
A32: Sprint 7 | B32: =INDEX('Roadmap Sprints'!$C$2:$C$9,MATCH(IF(A32="Cierre","Semana de cierre",A32),'Roadmap Sprints'!$A$2:$A$9,0)) | C32: =COUNTIFS('Backlog por Sprint'!$A$2:$A$71,$A32,'Backlog por Sprint'!$I$2:$I$71,"Plan original") | D32: =COUNTIFS('Backlog por Sprint'!$A$2:$A$71,$A32,'Backlog por Sprint'!$Q$2:$Q$71,"Hecha a tiempo") | E32: =COUNTIFS('Backlog por Sprint'!$A$2:$A$71,$A32,'Backlog por Sprint'!$Q$2:$Q$71,"Hecha con atraso") | F32: =COUNTIFS('Backlog por Sprint'!$A$2:$A$71,$A32,'Backlog por Sprint'!$Q$2:$Q$71,"Hecha (sin fecha)") | G32: =COUNTIFS('Backlog por Sprint'!$A$2:$A$71,$A32,'Backlog por Sprint'!$Q$2:$Q$71,"Pendiente atrasada") | H32: =COUNTIFS('Backlog por Sprint'!$A$2:$A$71,$A32,'Backlog por Sprint'!$Q$2:$Q$71,"Pendiente en plazo") | I32: =MAX(0,_xlfn.MAXIFS('Backlog por Sprint'!$O$2:$O$71,'Backlog por Sprint'!$A$2:$A$71,$A32,'Backlog por Sprint'!$I$2:$I$71,"Plan original")) | J32: =ROUND(I32/7,1)
A33: Cierre | B33: =INDEX('Roadmap Sprints'!$C$2:$C$9,MATCH(IF(A33="Cierre","Semana de cierre",A33),'Roadmap Sprints'!$A$2:$A$9,0)) | C33: =COUNTIFS('Backlog por Sprint'!$A$2:$A$71,$A33,'Backlog por Sprint'!$I$2:$I$71,"Plan original") | D33: =COUNTIFS('Backlog por Sprint'!$A$2:$A$71,$A33,'Backlog por Sprint'!$Q$2:$Q$71,"Hecha a tiempo") | E33: =COUNTIFS('Backlog por Sprint'!$A$2:$A$71,$A33,'Backlog por Sprint'!$Q$2:$Q$71,"Hecha con atraso") | F33: =COUNTIFS('Backlog por Sprint'!$A$2:$A$71,$A33,'Backlog por Sprint'!$Q$2:$Q$71,"Hecha (sin fecha)") | G33: =COUNTIFS('Backlog por Sprint'!$A$2:$A$71,$A33,'Backlog por Sprint'!$Q$2:$Q$71,"Pendiente atrasada") | H33: =COUNTIFS('Backlog por Sprint'!$A$2:$A$71,$A33,'Backlog por Sprint'!$Q$2:$Q$71,"Pendiente en plazo") | I33: =MAX(0,_xlfn.MAXIFS('Backlog por Sprint'!$O$2:$O$71,'Backlog por Sprint'!$A$2:$A$71,$A33,'Backlog por Sprint'!$I$2:$I$71,"Plan original")) | J33: =ROUND(I33/7,1)
A34: Total | C34: =SUM(C26:C33) | D34: =SUM(D26:D33) | E34: =SUM(E26:E33) | F34: =SUM(F26:F33) | G34: =SUM(G26:G33) | H34: =SUM(H26:H33) | I34: =MAX(I26:I33) | J34: =ROUND(I34/7,1)
A36: Cumplimiento a la fecha de corte (solo plan original)
A37: Indicador | B37: Actividades | C37: Días-persona
A38: Con vencimiento hasta el corte (debían estar hechas) | B38: =COUNTIFS('Backlog por Sprint'!$I$2:$I$71,"Plan original",'Backlog por Sprint'!$K$2:$K$71,"<="&Avance!$B$2) | C38: =SUMIFS('Backlog por Sprint'!$E$2:$E$71,'Backlog por Sprint'!$I$2:$I$71,"Plan original",'Backlog por Sprint'!$K$2:$K$71,"<="&Avance!$B$2)
A39: de ellas, hechas | B39: =COUNTIFS('Backlog por Sprint'!$I$2:$I$71,"Plan original",'Backlog por Sprint'!$K$2:$K$71,"<="&Avance!$B$2,'Backlog por Sprint'!$G$2:$G$71,"Hecho") | C39: =SUMIFS('Backlog por Sprint'!$E$2:$E$71,'Backlog por Sprint'!$I$2:$I$71,"Plan original",'Backlog por Sprint'!$K$2:$K$71,"<="&Avance!$B$2,'Backlog por Sprint'!$G$2:$G$71,"Hecho")
A40: de ellas, en proceso | B40: =COUNTIFS('Backlog por Sprint'!$I$2:$I$71,"Plan original",'Backlog por Sprint'!$K$2:$K$71,"<="&Avance!$B$2,'Backlog por Sprint'!$G$2:$G$71,"En proceso") | C40: =SUMIFS('Backlog por Sprint'!$E$2:$E$71,'Backlog por Sprint'!$I$2:$I$71,"Plan original",'Backlog por Sprint'!$K$2:$K$71,"<="&Avance!$B$2,'Backlog por Sprint'!$G$2:$G$71,"En proceso")
A41: de ellas, por hacer | B41: =B38-B39-B40 | C41: =C38-C39-C40
A42: Cumplimiento de lo comprometido (hechas / con vencimiento) | B42: =IF(B38=0,0,B39/B38) | C42: =IF(C38=0,0,C39/C38)
A43: Tiempo transcurrido del proyecto (inicio a demo) | B43: =(Avance!$B$2-'Roadmap Sprints'!$B$2+1)/('Roadmap Sprints'!$C$9-'Roadmap Sprints'!$B$2+1)
A44: Semanas transcurridas / semanas totales | B44: =ROUND((Avance!$B$2-'Roadmap Sprints'!$B$2+1)/7,1) | C44: =ROUND(('Roadmap Sprints'!$C$9-'Roadmap Sprints'!$B$2+1)/7,1)
...

Sheet Roadmap Sprints
A1: Sprint | B1: Inicio | C1: Fin | D1: Días hábiles | E1: Objetivo principal del sprint | F1: Hito / Entregable clave | G1: Foco del Técnico (maqueta)
A2: Sprint 1 | B2: 46258 | C2: 46271 | D2: =NETWORKDAYS(B2,C2) | E2: Descubrimiento, arquitectura y cotización. Definir backlog completo, levantar requerimientos con el cliente, diseñar arquitectura Firebase (Auth, Firestore/Realtime DB, Functions) y dejar lista la infraestructura base (proyecto GCP, repos, CI). En paralelo, diseñar el enfoque de simulación de datos para el módulo de ML predictivo (qué variables, qué patrones física-informados usar). | F2: Backlog priorizado + arquitectura aprobada + proyecto Firebase creado + diseño de la simulación de datos | G2: Terminar cotización de sensores/gateway; definir modelo de sensores a comprar
A3: Sprint 2 | B3: 46272 | C3: 46285 | D3: =NETWORKDAYS(B3,C3) | E3: Compra de sensores y arranque de desarrollo base. Gestionar compra/OC de sensores y gateway. Implementar Firebase Authentication y esquema de datos (Firestore) para lecturas de sensores. Generar el dataset simulado y entrenar la primera versión de los modelos de ML clásico (regresión / ARIMA-Prophet) con esos datos sintéticos. | F3: Sensores comprados (OC emitida) + Auth funcional + esquema de datos definido + primer modelo ML entrenado con datos simulados | G3: Recepción de sensores, pruebas de conexión básicas en banco (sin maqueta aún)
A4: Sprint 3 | B4: 46286 | C4: 46299 | D4: =NETWORKDAYS(B4,C4) | E4: Ingesta de datos y esqueleto de maqueta. Construir Cloud Functions que reciban datos de sensores y los escriban en la base de datos en tiempo real. Iniciar armado físico de la maqueta. Integrar el modelo ML (entrenado con datos simulados) al backend, exponiendo predicciones vía Function. | F4: Pipeline sensor → Function → Firestore funcionando con datos simulados + modelo ML servido desde el backend | G4: Armado estructural de la maqueta y montaje de sensores
A5: Sprint 4 | B5: 46300 | C5: 46313 | D5: =NETWORKDAYS(B5,C5) | E5: Primer end-to-end con datos reales. Maqueta enviando datos reales de al menos 2 sensores (ej. temperatura y pH). Construir el esqueleto del dashboard web con gráficos en tiempo real, incluyendo un primer panel con la proyección del modelo ML (aún entrenado solo con datos simulados). | F5: Demo interna: datos reales de la maqueta llegando al dashboard en vivo + primer panel predictivo visible | G5: Maqueta operativa con sensores críticos conectados y calibrados
A6: Sprint 5 | B6: 46314 | C6: 46327 | D6: =NETWORKDAYS(B6,C6) | E6: Visualización completa. Integrar todos los sensores (conductividad, consumo de agua, químicos). Construir vistas de consumo de químicos/agua y series históricas básicas. Empezar a recalibrar los modelos de ML con los primeros datos reales que ya entrega la maqueta. | F6: Dashboard muestra todas las variables clave en tiempo real + históricos + modelo ML empezando a usar datos reales | G6: Todos los sensores de la maqueta integrados y estables
A7: Sprint 6 | B7: 46328 | C7: 46341 | D7: =NETWORKDAYS(B7,C7) | E7: Roles, seguridad y robustez. Implementar roles de usuario (cliente/interno) y reglas de seguridad de Firestore. Manejo de errores, reconexión de sensores y pérdida de datos. Validar la precisión del modelo ML contra los datos reales acumulados y pulir el panel predictivo en el dashboard. | F7: Reglas de seguridad + control de acceso por rol + manejo de desconexiones + modelo ML validado con datos reales | G7: Pruebas de estabilidad de la maqueta en jornadas prolongadas (esto también alimenta el histórico real)
A8: Sprint 7 | B8: 46342 | C8: 46355 | D8: =NETWORKDAYS(B8,C8) | E8: Pruebas integrales y cierre técnico. Testing end-to-end, pruebas de carga con flujo continuo de datos, corrección de bugs, documentación técnica y de usuario, despliegue a ambiente estable. Pruebas de aceptación interna (UAT) y preparación del guion de demo, incluido el panel de ML predictivo. | F8: Ambiente de staging/producción estable y probado + MVP completo listo para UAT | G8: Ajustes finales de calibración, confiabilidad de sensores y preparación para transporte
A9: Semana de cierre | B9: 46356 | C9: 46360 | D9: =NETWORKDAYS(B9,C9) | E9: Semana de cierre y presentación. Buffer para imprevistos, corrección de bugs críticos de última hora, ensayo general con el equipo completo y presentación del MVP al cliente. Esta semana ya no tiene holgura extra: es el único colchón que queda si algo del cronograma se atrasó. | F9: Presentación del MVP al cliente (04-12-2026) | G9: Puesta a punto de la maqueta el día de la demo
A11: Nota: 'Días hábiles' se calcula con NETWORKDAYS y no descuenta feriados chilenos; ajustar manualmente si corresponde.

Sheet Historias de usuario
A1: Product Backlog: historias de usuario (requisitos funcionales) y habilitadores
A2: BORRADOR propuesto el 19-10-2026 a partir de las tareas del backlog; el equipo debe revisar redacción, criterios y prioridad. El avance se calcula desde las tareas vinculadas (columna 'Historia (ID)' del backlog).
A4: ID | B4: Tipo | C4: Historia de usuario / descripción | D4: Criterios de aceptación | E4: Prioridad | F4: Tareas | G4: Hechas | H4: En proceso | I4: Avance | J4: Estado
A5: HU-01 | B5: Historia de usuario | C5: Como operador, quiero ver en tiempo real el pH, la conductividad y la temperatura del ciclo en curso, para saber cómo avanza la limpieza. | D5: 1) Cada lectura nueva aparece en el dashboard sin recargar la página. 2) Cada tarjeta muestra valor, unidad y hora de la lectura. 3) Si una sonda no reporta o está saturada, la tarjeta lo indica en vez de mostrar un valor. | E5: Alta | F5: =COUNTIF('Backlog por Sprint'!$R$2:$R$71,A5) | G5: =COUNTIFS('Backlog por Sprint'!$R$2:$R$71,A5,'Backlog por Sprint'!$G$2:$G$71,"Hecho") | H5: =COUNTIFS('Backlog por Sprint'!$R$2:$R$71,A5,'Backlog por Sprint'!$G$2:$G$71,"En proceso") | I5: =IF(F5=0,0,G5/F5) | J5: =IF(F5=0,"Sin tareas",IF(G5=F5,"Hecha",IF(G5+H5>0,"En proceso","Por hacer")))
A6: HU-02 | B6: Historia de usuario | C6: Como operador, quiero ver en qué etapa del CIP está el ciclo y cuánto tiempo lleva, para coordinar la operación. | D6: 1) La barra muestra las etapas en orden y marca la actual. 2) Se ve el tiempo transcurrido de la etapa. 3) Las etapas fuera del alcance de las sondas se señalan como no monitoreadas. | E6: Media | F6: =COUNTIF('Backlog por Sprint'!$R$2:$R$71,A6) | G6: =COUNTIFS('Backlog por Sprint'!$R$2:$R$71,A6,'Backlog por Sprint'!$G$2:$G$71,"Hecho") | H6: =COUNTIFS('Backlog por Sprint'!$R$2:$R$71,A6,'Backlog por Sprint'!$G$2:$G$71,"En proceso") | I6: =IF(F6=0,0,G6/F6) | J6: =IF(F6=0,"Sin tareas",IF(G6=F6,"Hecha",IF(G6+H6>0,"En proceso","Por hacer")))
A7: HU-03 | B7: Historia de usuario | C7: Como operador, quiero recibir una alerta cuando una variable sale del rango de la etapa, para corregir a tiempo. | D7: 1) Una lectura fuera del umbral de su etapa crea una alerta con variable, valor, rango y hora. 2) Si la red reintenta el mismo mensaje no se duplica la alerta. 3) El historial de alertas queda visible en el dashboard. | E7: Alta | F7: =COUNTIF('Backlog por Sprint'!$R$2:$R$71,A7) | G7: =COUNTIFS('Backlog por Sprint'!$R$2:$R$71,A7,'Backlog por Sprint'!$G$2:$G$71,"Hecho") | H7: =COUNTIFS('Backlog por Sprint'!$R$2:$R$71,A7,'Backlog por Sprint'!$G$2:$G$71,"En proceso") | I7: =IF(F7=0,0,G7/F7) | J7: =IF(F7=0,"Sin tareas",IF(G7=F7,"Hecha",IF(G7+H7>0,"En proceso","Por hacer")))
A8: HU-04 | B8: Historia de usuario | C8: Como jefe de producción, quiero ver el historial de las últimas 24 horas y 7 días por variable, para comparar ciclos. | D8: 1) Se puede elegir la variable y el período (24 h o 7 días). 2) El gráfico muestra las lecturas de todos los ciclos del período. 3) Funciona con el índice de lecturas desplegado. | E8: Media | F8: =COUNTIF('Backlog por Sprint'!$R$2:$R$71,A8) | G8: =COUNTIFS('Backlog por Sprint'!$R$2:$R$71,A8,'Backlog por Sprint'!$G$2:$G$71,"Hecho") | H8: =COUNTIFS('Backlog por Sprint'!$R$2:$R$71,A8,'Backlog por Sprint'!$G$2:$G$71,"En proceso") | I8: =IF(F8=0,0,G8/F8) | J8: =IF(F8=0,"Sin tareas",IF(G8=F8,"Hecha",IF(G8+H8>0,"En proceso","Por hacer")))
A9: HU-05 | B9: Historia de usuario | C9: Como jefe de producción, quiero ver el consumo de agua y de químicos de cada ciclo, para optimizar recursos. | D9: 1) El consumo de agua se calcula desde el flujómetro cuando existe. 2) Si el valor es estimado (caudal nominal) se marca como estimado. 3) Se ve el total por ciclo y su tendencia. | E9: Media | F9: =COUNTIF('Backlog por Sprint'!$R$2:$R$71,A9) | G9: =COUNTIFS('Backlog por Sprint'!$R$2:$R$71,A9,'Backlog por Sprint'!$G$2:$G$71,"Hecho") | H9: =COUNTIFS('Backlog por Sprint'!$R$2:$R$71,A9,'Backlog por Sprint'!$G$2:$G$71,"En proceso") | I9: =IF(F9=0,0,G9/F9) | J9: =IF(F9=0,"Sin tareas",IF(G9=F9,"Hecha",IF(G9+H9>0,"En proceso","Por hacer")))
A10: HU-06 | B10: Historia de usuario | C10: Como jefe de producción, quiero ver indicadores al cerrar un ciclo, para evaluar si la limpieza fue eficiente. | D10: 1) Al finalizar un ciclo se calculan tiempo hasta agua limpia, arrastre químico, pendiente de conductividad y volumen. 2) Cada indicador muestra su método y si es medido o estimado. 3) Un ciclo sin datos útiles explica el motivo. | E10: Alta | F10: =COUNTIF('Backlog por Sprint'!$R$2:$R$71,A10) | G10: =COUNTIFS('Backlog por Sprint'!$R$2:$R$71,A10,'Backlog por Sprint'!$G$2:$G$71,"Hecho") | H10: =COUNTIFS('Backlog por Sprint'!$R$2:$R$71,A10,'Backlog por Sprint'!$G$2:$G$71,"En proceso") | I10: =IF(F10=0,0,G10/F10) | J10: =IF(F10=0,"Sin tareas",IF(G10=F10,"Hecha",IF(G10+H10>0,"En proceso","Por hacer")))
A11: HU-07 | B11: Historia de usuario | C11: Como jefe de producción, quiero una proyección de cuándo quedará limpio el enjuague y avisos de tendencias anómalas, para anticipar problemas. | D11: 1) El dashboard muestra una proyección en minutos con su nivel de confianza. 2) Se avisa cuando una variable tiende a salir de rango. 3) El modelo se valida contra datos reales de la maqueta antes de la demo. | E11: Alta | F11: =COUNTIF('Backlog por Sprint'!$R$2:$R$71,A11) | G11: =COUNTIFS('Backlog por Sprint'!$R$2:$R$71,A11,'Backlog por Sprint'!$G$2:$G$71,"Hecho") | H11: =COUNTIFS('Backlog por Sprint'!$R$2:$R$71,A11,'Backlog por Sprint'!$G$2:$G$71,"En proceso") | I11: =IF(F11=0,0,G11/F11) | J11: =IF(F11=0,"Sin tareas",IF(G11=F11,"Hecha",IF(G11+H11>0,"En proceso","Por hacer")))
A12: HU-08 | B12: Historia de usuario | C12: Como usuario, quiero iniciar sesión y ver solo lo que mi rol permite, para proteger la información de la planta. | D12: 1) Sin sesión no se accede al dashboard. 2) Admin, operador y visor ven y modifican solo lo que su rol permite, también a nivel de base de datos. 3) Las reglas se prueban con tests automáticos. | E12: Alta | F12: =COUNTIF('Backlog por Sprint'!$R$2:$R$71,A12) | G12: =COUNTIFS('Backlog por Sprint'!$R$2:$R$71,A12,'Backlog por Sprint'!$G$2:$G$71,"Hecho") | H12: =COUNTIFS('Backlog por Sprint'!$R$2:$R$71,A12,'Backlog por Sprint'!$G$2:$G$71,"En proceso") | I12: =IF(F12=0,0,G12/F12) | J12: =IF(F12=0,"Sin tareas",IF(G12=F12,"Hecha",IF(G12+H12>0,"En proceso","Por hacer")))
A13: HU-09 | B13: Historia de usuario | C13: Como administrador, quiero asignar roles a los usuarios, para controlar quién accede a qué. | D13: 1) Solo un admin puede cambiar un rol. 2) Un usuario nuevo parte como visor. 3) El cambio se refleja al volver a iniciar sesión. | E13: Media | F13: =COUNTIF('Backlog por Sprint'!$R$2:$R$71,A13) | G13: =COUNTIFS('Backlog por Sprint'!$R$2:$R$71,A13,'Backlog por Sprint'!$G$2:$G$71,"Hecho") | H13: =COUNTIFS('Backlog por Sprint'!$R$2:$R$71,A13,'Backlog por Sprint'!$G$2:$G$71,"En proceso") | I13: =IF(F13=0,0,G13/F13) | J13: =IF(F13=0,"Sin tareas",IF(G13=F13,"Hecha",IF(G13+H13>0,"En proceso","Por hacer")))
A14: HU-10 | B14: Historia de usuario | C14: Como administrador, quiero ver el estado de cada equipo (firmware, batería y última señal), para detectar sensores con problemas. | D14: 1) Se ve el firmware registrado y el reportado por el equipo. 2) Se ve la batería y la hora de la última señal y de la última medición. 3) Se avisa si un equipo deja de medir durante un ciclo. | E14: Baja | F14: =COUNTIF('Backlog por Sprint'!$R$2:$R$71,A14) | G14: =COUNTIFS('Backlog por Sprint'!$R$2:$R$71,A14,'Backlog por Sprint'!$G$2:$G$71,"Hecho") | H14: =COUNTIFS('Backlog por Sprint'!$R$2:$R$71,A14,'Backlog por Sprint'!$G$2:$G$71,"En proceso") | I14: =IF(F14=0,0,G14/F14) | J14: =IF(F14=0,"Sin tareas",IF(G14=F14,"Hecha",IF(G14+H14>0,"En proceso","Por hacer")))
A15: HU-11 | B15: Historia de usuario | C15: Como equipo del proyecto, quiero simular un ciclo CIP completo y controlarlo desde el dashboard, para demostrar y probar el sistema sin sensores. | D15: 1) El simulador recorre todas las etapas con valores realistas. 2) Se inicia y detiene desde un botón del dashboard. 3) Nunca escribe en producción sin indicarlo de forma explícita. | E15: Media | F15: =COUNTIF('Backlog por Sprint'!$R$2:$R$71,A15) | G15: =COUNTIFS('Backlog por Sprint'!$R$2:$R$71,A15,'Backlog por Sprint'!$G$2:$G$71,"Hecho") | H15: =COUNTIFS('Backlog por Sprint'!$R$2:$R$71,A15,'Backlog por Sprint'!$G$2:$G$71,"En proceso") | I15: =IF(F15=0,0,G15/F15) | J15: =IF(F15=0,"Sin tareas",IF(G15=F15,"Hecha",IF(G15+H15>0,"En proceso","Por hacer")))
A16: HU-12 | B16: Historia de usuario | C16: Como operador, quiero que las lecturas de los sensores lleguen solas desde la planta, para no registrar datos a mano. | D16: 1) Un uplink del WQS-LB se decodifica y se guarda en el ciclo en curso. 2) Payloads inválidos o de firmware no soportado se rechazan sin perder el dato crudo. 3) Se prueba con un sensor real de la maqueta. | E16: Alta | F16: =COUNTIF('Backlog por Sprint'!$R$2:$R$71,A16) | G16: =COUNTIFS('Backlog por Sprint'!$R$2:$R$71,A16,'Backlog por Sprint'!$G$2:$G$71,"Hecho") | H16: =COUNTIFS('Backlog por Sprint'!$R$2:$R$71,A16,'Backlog por Sprint'!$G$2:$G$71,"En proceso") | I16: =IF(F16=0,0,G16/F16) | J16: =IF(F16=0,"Sin tareas",IF(G16=F16,"Hecha",IF(G16+H16>0,"En proceso","Por hacer")))
... A22: GE-01 | B22: Gestión del proyecto | C22: Requerimientos, backlog, guion y presentación del MVP al cliente. | D22: Requerimientos validados con el cliente y demo presentada el 04-12-2026. | E22: Alta | F22: =COUNTIF('Backlog por Sprint'!$R$2:$R$71,A22) | G22: =COUNTIFS('Backlog por Sprint'!$R$2:$R$71,A22,'Backlog por Sprint'!$G$2:$G$71,"Hecho") | H22: =COUNTIFS('Backlog por Sprint'!$R$2:$R$71,A22,'Backlog por Sprint'!$G$2:$G$71,"En proceso") | I22: =IF(F22=0,0,G22/F22) | J22: =IF(F22=0,"Sin tareas",IF(G22=F22,"Hecha",IF(G22+H22>0,"En proceso","Por hacer")))
C23: Total de tareas vinculadas | F23: =SUM(F5:F22) | G23: =SUM(G5:G22) | H23: =SUM(H5:H22)
A25: Cómo leer esta hoja:
A26: • HU = historia de usuario: un requisito funcional escrito como 'Como <rol>, quiero <qué>, para <para qué>'.
A27: • HT = habilitador técnico: trabajo necesario que no entrega valor directo a un usuario (infraestructura, datos, calidad).
A28: • GE = gestión del proyecto. Los requisitos no funcionales están en la hoja 'Requisitos no funcionales'.
A29: • El total de tareas vinculadas debe ser 70 (todas las del backlog).

Sheet Requisitos no funcionales
A1: Requisitos no funcionales
A2: BORRADOR propuesto el 19-10-2026. Los valores objetivo de rendimiento y carga están por definir con el equipo y el cliente.
A4: ID | B4: Categoría | C4: Requisito | D4: Cómo se verifica | E4: Estado actual (evidencia)
A5: RNF-01 | B5: Seguridad | C5: Solo usuarios autenticados acceden al sistema y cada rol (admin, operador, visor) ve y modifica solo lo que le corresponde, también a nivel de base de datos. | D5: Tests de reglas de Firestore (functions/reglas) y prueba manual por rol. | E5: Parcial: reglas y tests existen; falta limitar qué campos puede escribir el operador.
A6: RNF-02 | B6: Seguridad | C6: Los secretos (clave del webhook, credenciales) nunca se guardan en el código ni en el repositorio. | D6: Revisión del repositorio y uso de Secret Manager. | E6: Cumple: TTN_WEBHOOK_SECRET en Secret Manager; .secret.local y .env.local fuera de git.
A7: RNF-03 | B7: Seguridad | C7: Solo se aceptan datos de dispositivos registrados y mensajes autenticados. | D7: Caso 'dispositivo desconocido' del simulador TTN y respuesta 401 de /api/ingest sin clave. | E7: Cumple según SPRINT1.md y README de pruebas.
A8: RNF-04 | B8: Confiabilidad | C8: Un mismo mensaje reenviado por la red no genera lecturas ni alertas duplicadas (idempotencia). | D8: Caso 5 de 'npm run sim:ttn'. | E8: Cumple.
A9: RNF-05 | B9: Confiabilidad | C9: Un dato fuera del rango físico de la sonda se rechaza o se marca como saturado o fuera de operación; nunca se muestra como válido. | D9: Tests unitarios de ingest y del decoder. | E9: Cumple.
A10: RNF-06 | B10: Rendimiento | C10: Una lectura aparece en el dashboard pocos segundos después de llegar a la nube (valor objetivo por definir; propuesta: menos de 10 s). | D10: Prueba de rendimiento midiendo desde received_at hasta la pantalla. | E10: Sin medir: no hay pruebas de rendimiento.
A11: RNF-07 | B11: Rendimiento / Escalabilidad | C11: El sistema soporta el flujo continuo de varios sensores durante un ciclo completo sin perder lecturas (carga objetivo por definir). | D11: Prueba de carga del Sprint 7. | E11: Sin medir.
A12: RNF-08 | B12: Disponibilidad | C12: La plataforma está disponible durante los ciclos de limpieza; usa servicios administrados de Google Cloud en southamerica-west1 (Santiago). | D12: Monitoreo de Firebase y prueba de estabilidad de 8 h o más. | E12: Parcial: desplegado en Firebase; falta la prueba de estabilidad.
A13: RNF-09 | B13: Portabilidad | C13: Cualquier integrante puede levantar el entorno de desarrollo en su equipo con un procedimiento documentado y reproducible (Docker). | D13: docker-compose con emuladores, web y scripts; instrucciones en el README. | E13: Falta: no hay Docker; los emuladores fallaron en un equipo por un problema de red de Java.
A14: RNF-10 | B14: Usabilidad | C14: Un dato estimado se distingue siempre de uno medido (borde, color y prefijo '≈'), para no inducir a error al operador. | D14: Revisión del dashboard. | E14: Cumple en los indicadores del ciclo.
A15: RNF-11 | B15: Mantenibilidad | C15: El código tiene pruebas automatizadas y ningún script toca producción sin flags explícitos. | D15: npm test en functions y web (291 tests al 18-10-2026); guardarraíles en scripts/entorno.js. | E15: Cumple.

Sheet Backlog por Sprint
A1: Sprint | B1: Categoría | C1: Tarea / Historia de usuario | D1: Responsable sugerido | E1: Estimación (días) | F1: Dependencias | G1: Estado | H1: Observaciones | I1: Origen | J1: Inicio plan | K1: Fin plan (compromiso) | L1: Término real (evidencia) | M1: Días hábiles esperados | N1: Días hábiles ejecutados | O1: Atraso (días corridos) | P1: Atraso (semanas) | Q1: Situación | R1: Historia (ID)
A2: Sprint 1 | B2: Gestión de proyecto | C2: Levantar requerimientos detallados con el cliente y definir criterios de aceptación del MVP | D2: Felipe | E2: 3 | F2: - | G2: Hecho | I2: Plan original | J2: =IF($I2="Plan original",INDEX('Roadmap Sprints'!$B$2:$B$9,MATCH(IF($A2="Cierre","Semana de cierre",$A2),'Roadmap Sprints'!$A$2:$A$9,0)),"") | K2: =IF($I2="Plan original",INDEX('Roadmap Sprints'!$C$2:$C$9,MATCH(IF($A2="Cierre","Semana de cierre",$A2),'Roadmap Sprints'!$A$2:$A$9,0)),"") | M2: =IF(J2="","",NETWORKDAYS(J2,K2)) | N2: =IF(J2="","",IF(L2<>"",IF(L2<J2,0,NETWORKDAYS(J2,L2)),IF(G2="Hecho","",IF(Avance!$B$2<J2,0,NETWORKDAYS(J2,Avance!$B$2))))) | O2: =IF(J2="","n/a",IF(L2<>"",L2-K2,IF(G2="Hecho","s/d",MAX(0,Avance!$B$2-K2)))) | P2: =IF(ISNUMBER(O2),ROUND(O2/7,1),O2) | Q2: =IF(J2="","No planificada",IF(G2="Hecho",IF(L2="","Hecha (sin fecha)",IF(L2>K2,"Hecha con atraso","Hecha a tiempo")),IF(Avance!$B$2>K2,"Pendiente atrasada","Pendiente en plazo"))) | R2: GE-01
A3: Sprint 1 | B3: Gestión de proyecto | C3: Armar backlog priorizado y tablero ágil (Jira/Trello/Linear) | D3: Tamara | E3: 2 | F3: - | G3: Hecho | I3: Plan original | J3: =IF($I3="Plan original",INDEX('Roadmap Sprints'!$B$2:$B$9,MATCH(IF($A3="Cierre","Semana de cierre",$A3),'Roadmap Sprints'!$A$2:$A$9,0)),"") | K3: =IF($I3="Plan original",INDEX('Roadmap Sprints'!$C$2:$C$9,MATCH(IF($A3="Cierre","Semana de cierre",$A3),'Roadmap Sprints'!$A$2:$A$9,0)),"") | M3: =IF(J3="","",NETWORKDAYS(J3,K3)) | N3: =IF(J3="","",IF(L3<>"",IF(L3<J3,0,NETWORKDAYS(J3,L3)),IF(G3="Hecho","",IF(Avance!$B$2<J3,0,NETWORKDAYS(J3,Avance!$B$2))))) | O3: =IF(J3="","n/a",IF(L3<>"",L3-K3,IF(G3="Hecho","s/d",MAX(0,Avance!$B$2-K3)))) | P3: =IF(ISNUMBER(O3),ROUND(O3/7,1),O3) | Q3: =IF(J3="","No planificada",IF(G3="Hecho",IF(L3="","Hecha (sin fecha)",IF(L3>K3,"Hecha con atraso","Hecha a tiempo")),IF(Avance!$B$2>K3,"Pendiente atrasada","Pendiente en plazo"))) | R3: GE-01
A4: Sprint 1 | B4: Hardware / Sensores | C4: Finalizar cotización de sensores de temperatura, pH, conductividad y caudal/consumo | D4: Felipe | E4: 5 | F4: - | G4: Hecho | H4: Cotización y orden de compra en Gestion Sensores/ (commit d758be2, 07-oct-2026). | I4: Plan original | J4: =IF($I4="Plan original",INDEX('Roadmap Sprints'!$B$2:$B$9,MATCH(IF($A4="Cierre","Semana de cierre",$A4),'Roadmap Sprints'!$A$2:$A$9,0)),"") | K4: =IF($I4="Plan original",INDEX('Roadmap Sprints'!$C$2:$C$9,MATCH(IF($A4="Cierre","Semana de cierre",$A4),'Roadmap Sprints'!$A$2:$A$9,0)),"") | L4: 46302 | M4: =IF(J4="","",NETWORKDAYS(J4,K4)) | N4: =IF(J4="","",IF(L4<>"",IF(L4<J4,0,NETWORKDAYS(J4,L4)),IF(G4="Hecho","",IF(Avance!$B$2<J4,0,NETWORKDAYS(J4,Avance!$B$2))))) | O4: =IF(J4="","n/a",IF(L4<>"",L4-K4,IF(G4="Hecho","s/d",MAX(0,Avance!$B$2-K4)))) | P4: =IF(ISNUMBER(O4),ROUND(O4/7,1),O4) | Q4: =IF(J4="","No planificada",IF(G4="Hecho",IF(L4="","Hecha (sin fecha)",IF(L4>K4,"Hecha con atraso","Hecha a tiempo")),IF(Avance!$B$2>K4,"Pendiente atrasada","Pendiente en plazo"))) | R4: HT-03
A5: Sprint 1 | B5: Backend / Firebase | C5: Crear proyecto en Firebase/GCP y definir estructura (Auth, Firestore, Functions, Hosting) | D5: Humberto y cristian | E5: 3 | F5: - | G5: Hecho | H5: Proyecto stormcip-972bd en producción; Functions, reglas e índices desplegados (SPRINT3.md §2). | I5: Plan original | J5: =IF($I5="Plan original",INDEX('Roadmap Sprints'!$B$2:$B$9,MATCH(IF($A5="Cierre","Semana de cierre",$A5),'Roadmap Sprints'!$A$2:$A$9,0)),"") | K5: =IF($I5="Plan original",INDEX('Roadmap Sprints'!$C$2:$C$9,MATCH(IF($A5="Cierre","Semana de cierre",$A5),'Roadmap Sprints'!$A$2:$A$9,0)),"") | L5: 46286 | M5: =IF(J5="","",NETWORKDAYS(J5,K5)) | N5: =IF(J5="","",IF(L5<>"",IF(L5<J5,0,NETWORKDAYS(J5,L5)),IF(G5="Hecho","",IF(Avance!$B$2<J5,0,NETWORKDAYS(J5,Avance!$B$2))))) | O5: =IF(J5="","n/a",IF(L5<>"",L5-K5,IF(G5="Hecho","s/d",MAX(0,Avance!$B$2-K5)))) | P5: =IF(ISNUMBER(O5),ROUND(O5/7,1),O5) | Q5: =IF(J5="","No planificada",IF(G5="Hecho",IF(L5="","Hecha (sin fecha)",IF(L5>K5,"Hecha con atraso","Hecha a tiempo")),IF(Avance!$B$2>K5,"Pendiente atrasada","Pendiente en plazo"))) | R5: HT-01
A6: Sprint 1 | B6: Backend / Firebase | C6: Diseñar modelo de datos para lecturas de sensores en Firestore/Realtime DB | D6: Humberto y cristian | E6: 3 | F6: Proyecto Firebase creado | G6: Hecho | H6: Modelo v2 documentado en Base de datos/modelo-datos-sensores.md (el manual de sensores ya se recibió). | I6: Plan original | J6: =IF($I6="Plan original",INDEX('Roadmap Sprints'!$B$2:$B$9,MATCH(IF($A6="Cierre","Semana de cierre",$A6),'Roadmap Sprints'!$A$2:$A$9,0)),"") | K6: =IF($I6="Plan original",INDEX('Roadmap Sprints'!$C$2:$C$9,MATCH(IF($A6="Cierre","Semana de cierre",$A6),'Roadmap Sprints'!$A$2:$A$9,0)),"") | L6: 46290 | M6: =IF(J6="","",NETWORKDAYS(J6,K6)) | N6: =IF(J6="","",IF(L6<>"",IF(L6<J6,0,NETWORKDAYS(J6,L6)),IF(G6="Hecho","",IF(Avance!$B$2<J6,0,NETWORKDAYS(J6,Avance!$B$2))))) | O6: =IF(J6="","n/a",IF(L6<>"",L6-K6,IF(G6="Hecho","s/d",MAX(0,Avance!$B$2-K6)))) | P6: =IF(ISNUMBER(O6),ROUND(O6/7,1),O6) | Q6: =IF(J6="","No planificada",IF(G6="Hecho",IF(L6="","Hecha (sin fecha)",IF(L6>K6,"Hecha con atraso","Hecha a tiempo")),IF(Avance!$B$2>K6,"Pendiente atrasada","Pendiente en plazo"))) | R6: HT-02
A7: Sprint 1 | B7: Análisis Predictivo | C7: Diseñar el enfoque de simulación de datos (variables, rangos y patrones física-informados de un ciclo CIP) para poder entrenar los modelos de ML sin esperar datos reales | D7: Dev Backend | E7: 3 | F7: - | G7: Por hacer | H7: Esto más adelante. Existe un simulador CIP para la demo (functions/src/simulacion/modeloCip.ts), pero no el diseño de datos para ML. Se retoma tras la revisión de manuales (oct-2026). | I7: Plan original | J7: =IF($I7="Plan original",INDEX('Roadmap Sprints'!$B$2:$B$9,MATCH(IF($A7="Cierre","Semana de cierre",$A7),'Roadmap Sprints'!$A$2:$A$9,0)),"") | K7: =IF($I7="Plan original",INDEX('Roadmap Sprints'!$C$2:$C$9,MATCH(IF($A7="Cierre","Semana de cierre",$A7),'Roadmap Sprints'!$A$2:$A$9,0)),"") | M7: =IF(J7="","",NETWORKDAYS(J7,K7)) | N7: =IF(J7="","",IF(L7<>"",IF(L7<J7,0,NETWORKDAYS(J7,L7)),IF(G7="Hecho","",IF(Avance!$B$2<J7,0,NETWORKDAYS(J7,Avance!$B$2))))) | O7: =IF(J7="","n/a",IF(L7<>"",L7-K7,IF(G7="Hecho","s/d",MAX(0,Avance!$B$2-K7)))) | P7: =IF(ISNUMBER(O7),ROUND(O7/7,1),O7) | Q7: =IF(J7="","No planificada",IF(G7="Hecho",IF(L7="","Hecha (sin fecha)",IF(L7>K7,"Hecha con atraso","Hecha a tiempo")),IF(Avance!$B$2>K7,"Pendiente atrasada","Pendiente en plazo"))) | R7: HU-07
A8: Sprint 2 | B8: Hardware / Sensores | C8: Emitir orden de compra de sensores y gateway/microcontrolador (ej. ESP32) | D8: Felipe | E8: 3 | F8: Cotización aprobada | G8: Hecho | H8: OC en Gestion Sensores/OrdenDeCompraSensores.pdf. Pendiente confirmar recepción e instalación de los sensores. | I8: Plan original | J8: =IF($I8="Plan original",INDEX('Roadmap Sprints'!$B$2:$B$9,MATCH(IF($A8="Cierre","Semana de cierre",$A8),'Roadmap Sprints'!$A$2:$A$9,0)),"") | K8: =IF($I8="Plan original",INDEX('Roadmap Sprints'!$C$2:$C$9,MATCH(IF($A8="Cierre","Semana de cierre",$A8),'Roadmap Sprints'!$A$2:$A$9,0)),"") | L8: 46302 | M8: =IF(J8="","",NETWORKDAYS(J8,K8)) | N8: =IF(J8="","",IF(L8<>"",IF(L8<J8,0,NETWORKDAYS(J8,L8)),IF(G8="Hecho","",IF(Avance!$B$2<J8,0,NETWORKDAYS(J8,Avance!$B$2))))) | O8: =IF(J8="","n/a",IF(L8<>"",L8-K8,IF(G8="Hecho","s/d",MAX(0,Avance!$B$2-K8)))) | P8: =IF(ISNUMBER(O8),ROUND(O8/7,1),O8) | Q8: =IF(J8="","No planificada",IF(G8="Hecho",IF(L8="","Hecha (sin fecha)",IF(L8>K8,"Hecha con atraso","Hecha a tiempo")),IF(Avance!$B$2>K8,"Pendiente atrasada","Pendiente en plazo"))) | R8: HT-03
A9: Sprint 2 | B9: Auth / Frontend | C9: Implementar Firebase Authentication (login cliente / interno) | D9: Humberto | E9: 5 | F9: Proyecto Firebase creado | G9: Hecho | H9: Login con roles admin / operador / visor (custom claims). | I9: Plan original | J9: =IF($I9="Plan original",INDEX('Roadmap Sprints'!$B$2:$B$9,MATCH(IF($A9="Cierre","Semana de cierre",$A9),'Roadmap Sprints'!$A$2:$A$9,0)),"") | K9: =IF($I9="Plan original",INDEX('Roadmap Sprints'!$C$2:$C$9,MATCH(IF($A9="Cierre","Semana de cierre",$A9),'Roadmap Sprints'!$A$2:$A$9,0)),"") | L9: 46286 | M9: =IF(J9="","",NETWORKDAYS(J9,K9)) | N9: =IF(J9="","",IF(L9<>"",IF(L9<J9,0,NETWORKDAYS(J9,L9)),IF(G9="Hecho","",IF(Avance!$B$2<J9,0,NETWORKDAYS(J9,Avance!$B$2))))) | O9: =IF(J9="","n/a",IF(L9<>"",L9-K9,IF(G9="Hecho","s/d",MAX(0,Avance!$B$2-K9)))) | P9: =IF(ISNUMBER(O9),ROUND(O9/7,1),O9) | Q9: =IF(J9="","No planificada",IF(G9="Hecho",IF(L9="","Hecha (sin fecha)",IF(L9>K9,"Hecha con atraso","Hecha a tiempo")),IF(Avance!$B$2>K9,"Pendiente atrasada","Pendiente en plazo"))) | R9: HU-08
A10: Sprint 2 | B10: Frontend / Dashboard | C10: Scaffolding de la app web (framework, rutas, layout base, conexión a Firebase) | D10: Humberto | E10: 5 | F10: Proyecto Firebase creado | G10: Hecho | H10: App Next.js en Aplicación/stormcip/web. | I10: Plan original | J10: =IF($I10="Plan original",INDEX('Roadmap Sprints'!$B$2:$B$9,MATCH(IF($A10="Cierre","Semana de cierre",$A10),'Roadmap Sprints'!$A$2:$A$9,0)),"") | K10: =IF($I10="Plan original",INDEX('Roadmap Sprints'!$C$2:$C$9,MATCH(IF($A10="Cierre","Semana de cierre",$A10),'Roadmap Sprints'!$A$2:$A$9,0)),"") | L10: 46296 | M10: =IF(J10="","",NETWORKDAYS(J10,K10)) | N10: =IF(J10="","",IF(L10<>"",IF(L10<J10,0,NETWORKDAYS(J10,L10)),IF(G10="Hecho","",IF(Avance!$B$2<J10,0,NETWORKDAYS(J10,Avance!$B$2))))) | O10: =IF(J10="","n/a",IF(L10<>"",L10-K10,IF(G10="Hecho","s/d",MAX(0,Avance!$B$2-K10)))) | P10: =IF(ISNUMBER(O10),ROUND(O10/7,1),O10) | Q10: =IF(J10="","No planificada",IF(G10="Hecho",IF(L10="","Hecha (sin fecha)",IF(L10>K10,"Hecha con atraso","Hecha a tiempo")),IF(Avance!$B$2>K10,"Pendiente atrasada","Pendiente en plazo"))) | R10: HU-01
A11: Sprint 2 | B11: Backend / Firebase | C11: Función HTTP/Callable para recibir datos simulados de sensores | D11: Humberto y cristian | E11: 3 | F11: Modelo de datos definido | G11: Hecho | H11: ingestLectura (POST /api/ingest) y simuladores en scripts/. | I11: Plan original | J11: =IF($I11="Plan original",INDEX('Roadmap Sprints'!$B$2:$B$9,MATCH(IF($A11="Cierre","Semana de cierre",$A11),'Roadmap Sprints'!$A$2:$A$9,0)),"") | K11: =IF($I11="Plan original",INDEX('Roadmap Sprints'!$C$2:$C$9,MATCH(IF($A11="Cierre","Semana de cierre",$A11),'Roadmap Sprints'!$A$2:$A$9,0)),"") | L11: 46286 | M11: =IF(J11="","",NETWORKDAYS(J11,K11)) | N11: =IF(J11="","",IF(L11<>"",IF(L11<J11,0,NETWORKDAYS(J11,L11)),IF(G11="Hecho","",IF(Avance!$B$2<J11,0,NETWORKDAYS(J11,Avance!$B$2))))) | O11: =IF(J11="","n/a",IF(L11<>"",L11-K11,IF(G11="Hecho","s/d",MAX(0,Avance!$B$2-K11)))) | P11: =IF(ISNUMBER(O11),ROUND(O11/7,1),O11) | Q11: =IF(J11="","No planificada",IF(G11="Hecho",IF(L11="","Hecha (sin fecha)",IF(L11>K11,"Hecha con atraso","Hecha a tiempo")),IF(Avance!$B$2>K11,"Pendiente atrasada","Pendiente en plazo"))) | R11: HU-12
A12: Sprint 2 | B12: Análisis Predictivo | C12: Generar el dataset histórico simulado (script Python) con los patrones definidos en Sprint 1 | D12: Dev Backend | E12: 3 | F12: Diseño de la simulación | G12: Por hacer | H12: esto mas adelante | I12: Plan original | J12: =IF($I12="Plan original",INDEX('Roadmap Sprints'!$B$2:$B$9,MATCH(IF($A12="Cierre","Semana de cierre",$A12),'Roadmap Sprints'!$A$2:$A$9,0)),"") | K12: =IF($I12="Plan original",INDEX('Roadmap Sprints'!$C$2:$C$9,MATCH(IF($A12="Cierre","Semana de cierre",$A12),'Roadmap Sprints'!$A$2:$A$9,0)),"") | M12: =IF(J12="","",NETWORKDAYS(J12,K12)) | N12: =IF(J12="","",IF(L12<>"",IF(L12<J12,0,NETWORKDAYS(J12,L12)),IF(G12="Hecho","",IF(Avance!$B$2<J12,0,NETWORKDAYS(J12,Avance!$B$2))))) | O12: =IF(J12="","n/a",IF(L12<>"",L12-K12,IF(G12="Hecho","s/d",MAX(0,Avance!$B$2-K12)))) | P12: =IF(ISNUMBER(O12),ROUND(O12/7,1),O12) | Q12: =IF(J12="","No planificada",IF(G12="Hecho",IF(L12="","Hecha (sin fecha)",IF(L12>K12,"Hecha con atraso","Hecha a tiempo")),IF(Avance!$B$2>K12,"Pendiente atrasada","Pendiente en plazo"))) | R12: HU-07
A13: Sprint 2 | B13: Análisis Predictivo | C13: Entrenar la primera versión de los modelos de ML clásico (regresión / ARIMA-Prophet) con el dataset simulado | D13: Dev Backend | E13: 4 | F13: Dataset simulado generado | G13: Por hacer | H13: esto mas adelante | I13: Plan original | J13: =IF($I13="Plan original",INDEX('Roadmap Sprints'!$B$2:$B$9,MATCH(IF($A13="Cierre","Semana de cierre",$A13),'Roadmap Sprints'!$A$2:$A$9,0)),"") | K13: =IF($I13="Plan original",INDEX('Roadmap Sprints'!$C$2:$C$9,MATCH(IF($A13="Cierre","Semana de cierre",$A13),'Roadmap Sprints'!$A$2:$A$9,0)),"") | M13: =IF(J13="","",NETWORKDAYS(J13,K13)) | N13: =IF(J13="","",IF(L13<>"",IF(L13<J13,0,NETWORKDAYS(J13,L13)),IF(G13="Hecho","",IF(Avance!$B$2<J13,0,NETWORKDAYS(J13,Avance!$B$2))))) | O13: =IF(J13="","n/a",IF(L13<>"",L13-K13,IF(G13="Hecho","s/d",MAX(0,Avance!$B$2-K13)))) | P13: =IF(ISNUMBER(O13),ROUND(O13/7,1),O13) | Q13: =IF(J13="","No planificada",IF(G13="Hecho",IF(L13="","Hecha (sin fecha)",IF(L13>K13,"Hecha con atraso","Hecha a tiempo")),IF(Avance!$B$2>K13,"Pendiente atrasada","Pendiente en plazo"))) | R13: HU-07
A14: Sprint 3 | B14: Hardware / Sensores | C14: Armado estructural de la maqueta (bomba, cañerías, estanques de prueba) | D14: Técnico | E14: 21 | F14: Sensores recibidos | G14: En proceso | H14: Esto es en paralelo. El técnico ya armó el modelo del flujo en una maqueta a escala reducida (18-oct-2026); faltan los sensores. | I14: Plan original | J14: =IF($I14="Plan original",INDEX('Roadmap Sprints'!$B$2:$B$9,MATCH(IF($A14="Cierre","Semana de cierre",$A14),'Roadmap Sprints'!$A$2:$A$9,0)),"") | K14: =IF($I14="Plan original",INDEX('Roadmap Sprints'!$C$2:$C$9,MATCH(IF($A14="Cierre","Semana de cierre",$A14),'Roadmap Sprints'!$A$2:$A$9,0)),"") | M14: =IF(J14="","",NETWORKDAYS(J14,K14)) | N14: =IF(J14="","",IF(L14<>"",IF(L14<J14,0,NETWORKDAYS(J14,L14)),IF(G14="Hecho","",IF(Avance!$B$2<J14,0,NETWORKDAYS(J14,Avance!$B$2))))) | O14: =IF(J14="","n/a",IF(L14<>"",L14-K14,IF(G14="Hecho","s/d",MAX(0,Avance!$B$2-K14)))) | P14: =IF(ISNUMBER(O14),ROUND(O14/7,1),O14) | Q14: =IF(J14="","No planificada",IF(G14="Hecho",IF(L14="","Hecha (sin fecha)",IF(L14>K14,"Hecha con atraso","Hecha a tiempo")),IF(Avance!$B$2>K14,"Pendiente atrasada","Pendiente en plazo"))) | R14: HT-03
A15: Sprint 3 | B15: Hardware / Sensores | C15: Montaje y cableado de sensores en la maqueta | D15: Técnico | E15: 21 | F15: Armado estructural | G15: Por hacer | H15: Esto es en paralelo. Los sensores aún no están instalados en la maqueta (18-oct-2026). | I15: Plan original | J15: =IF($I15="Plan original",INDEX('Roadmap Sprints'!$B$2:$B$9,MATCH(IF($A15="Cierre","Semana de cierre",$A15),'Roadmap Sprints'!$A$2:$A$9,0)),"") | K15: =IF($I15="Plan original",INDEX('Roadmap Sprints'!$C$2:$C$9,MATCH(IF($A15="Cierre","Semana de cierre",$A15),'Roadmap Sprints'!$A$2:$A$9,0)),"") | M15: =IF(J15="","",NETWORKDAYS(J15,K15)) | N15: =IF(J15="","",IF(L15<>"",IF(L15<J15,0,NETWORKDAYS(J15,L15)),IF(G15="Hecho","",IF(Avance!$B$2<J15,0,NETWORKDAYS(J15,Avance!$B$2))))) | O15: =IF(J15="","n/a",IF(L15<>"",L15-K15,IF(G15="Hecho","s/d",MAX(0,Avance!$B$2-K15)))) | P15: =IF(ISNUMBER(O15),ROUND(O15/7,1),O15) | Q15: =IF(J15="","No planificada",IF(G15="Hecho",IF(L15="","Hecha (sin fecha)",IF(L15>K15,"Hecha con atraso","Hecha a tiempo")),IF(Avance!$B$2>K15,"Pendiente atrasada","Pendiente en plazo"))) | R15: HT-03
A16: Sprint 3 | B16: Backend / Firebase | C16: Cloud Function de ingesta de datos reales del gateway → Firestore/Realtime DB | D16: Humberto | E16: 5 | F16: Función con datos simulados | G16: Hecho | H16: Implementada por Humberto (en el plan figuraba Tamara). ttnUplink desplegada; falta probarla con el sensor real. | I16: Plan original | J16: =IF($I16="Plan original",INDEX('Roadmap Sprints'!$B$2:$B$9,MATCH(IF($A16="Cierre","Semana de cierre",$A16),'Roadmap Sprints'!$A$2:$A$9,0)),"") | K16: =IF($I16="Plan original",INDEX('Roadmap Sprints'!$C$2:$C$9,MATCH(IF($A16="Cierre","Semana de cierre",$A16),'Roadmap Sprints'!$A$2:$A$9,0)),"") | L16: 46291 | M16: =IF(J16="","",NETWORKDAYS(J16,K16)) | N16: =IF(J16="","",IF(L16<>"",IF(L16<J16,0,NETWORKDAYS(J16,L16)),IF(G16="Hecho","",IF(Avance!$B$2<J16,0,NETWORKDAYS(J16,Avance!$B$2))))) | O16: =IF(J16="","n/a",IF(L16<>"",L16-K16,IF(G16="Hecho","s/d",MAX(0,Avance!$B$2-K16)))) | P16: =IF(ISNUMBER(O16),ROUND(O16/7,1),O16) | Q16: =IF(J16="","No planificada",IF(G16="Hecho",IF(L16="","Hecha (sin fecha)",IF(L16>K16,"Hecha con atraso","Hecha a tiempo")),IF(Avance!$B$2>K16,"Pendiente atrasada","Pendiente en plazo"))) | R16: HU-12
A17: Sprint 3 | B17: Frontend / Dashboard | C17: Esqueleto de dashboard con gráficos en tiempo real (librería de charts) | D17: Cristian | E17: 5 | F17: Scaffolding app web | G17: Hecho | H17: Dashboard desplegado en https://stormcip-972bd.web.app (SPRINT3.md). | I17: Plan original | J17: =IF($I17="Plan original",INDEX('Roadmap Sprints'!$B$2:$B$9,MATCH(IF($A17="Cierre","Semana de cierre",$A17),'Roadmap Sprints'!$A$2:$A$9,0)),"") | K17: =IF($I17="Plan original",INDEX('Roadmap Sprints'!$C$2:$C$9,MATCH(IF($A17="Cierre","Semana de cierre",$A17),'Roadmap Sprints'!$A$2:$A$9,0)),"") | L17: 46296 | M17: =IF(J17="","",NETWORKDAYS(J17,K17)) | N17: =IF(J17="","",IF(L17<>"",IF(L17<J17,0,NETWORKDAYS(J17,L17)),IF(G17="Hecho","",IF(Avance!$B$2<J17,0,NETWORKDAYS(J17,Avance!$B$2))))) | O17: =IF(J17="","n/a",IF(L17<>"",L17-K17,IF(G17="Hecho","s/d",MAX(0,Avance!$B$2-K17)))) | P17: =IF(ISNUMBER(O17),ROUND(O17/7,1),O17) | Q17: =IF(J17="","No planificada",IF(G17="Hecho",IF(L17="","Hecha (sin fecha)",IF(L17>K17,"Hecha con atraso","Hecha a tiempo")),IF(Avance!$B$2>K17,"Pendiente atrasada","Pendiente en plazo"))) | R17: HU-01
A18: Sprint 3 | B18: Análisis Predictivo | C18: Integrar el modelo ML entrenado al backend (Cloud Function que sirva predicciones) | D18: Dev Backend | E18: 4 | F18: Modelo entrenado con datos simulados | G18: Por hacer | H18: Esto más adelante. No entregado en Sprint 3 (SPRINT3.md §3); depende de entrenar el primer modelo. | I18: Plan original | J18: =IF($I18="Plan original",INDEX('Roadmap Sprints'!$B$2:$B$9,MATCH(IF($A18="Cierre","Semana de cierre",$A18),'Roadmap Sprints'!$A$2:$A$9,0)),"") | K18: =IF($I18="Plan original",INDEX('Roadmap Sprints'!$C$2:$C$9,MATCH(IF($A18="Cierre","Semana de cierre",$A18),'Roadmap Sprints'!$A$2:$A$9,0)),"") | M18: =IF(J18="","",NETWORKDAYS(J18,K18)) | N18: =IF(J18="","",IF(L18<>"",IF(L18<J18,0,NETWORKDAYS(J18,L18)),IF(G18="Hecho","",IF(Avance!$B$2<J18,0,NETWORKDAYS(J18,Avance!$B$2))))) | O18: =IF(J18="","n/a",IF(L18<>"",L18-K18,IF(G18="Hecho","s/d",MAX(0,Avance!$B$2-K18)))) | P18: =IF(ISNUMBER(O18),ROUND(O18/7,1),O18) | Q18: =IF(J18="","No planificada",IF(G18="Hecho",IF(L18="","Hecha (sin fecha)",IF(L18>K18,"Hecha con atraso","Hecha a tiempo")),IF(Avance!$B$2>K18,"Pendiente atrasada","Pendiente en plazo"))) | R18: HU-07
A19: Sprint 3 | B19: Hardware / Sensores | C19: Reunir información técnica de los sensores LoRaWAN (WQS-LB) en la carpeta de evidencias | D19: Felipe | E19: 1 | F19: - | G19: Hecho | H19: Commits b1debe1 y 0c1f9b2 (21-sep). Datasheet, certificaciones y firmware. [Estimación retroactiva] | I19: Agregada (no planificada) | J19: =IF($I19="Plan original",INDEX('Roadmap Sprints'!$B$2:$B$9,MATCH(IF($A19="Cierre","Semana de cierre",$A19),'Roadmap Sprints'!$A$2:$A$9,0)),"") | K19: =IF($I19="Plan original",INDEX('Roadmap Sprints'!$C$2:$C$9,MATCH(IF($A19="Cierre","Semana de cierre",$A19),'Roadmap Sprints'!$A$2:$A$9,0)),"") | L19: 46286 | M19: =IF(J19="","",NETWORKDAYS(J19,K19)) | N19: =IF(J19="","",IF(L19<>"",IF(L19<J19,0,NETWORKDAYS(J19,L19)),IF(G19="Hecho","",IF(Avance!$B$2<J19,0,NETWORKDAYS(J19,Avance!$B$2))))) | O19: =IF(J19="","n/a",IF(L19<>"",L19-K19,IF(G19="Hecho","s/d",MAX(0,Avance!$B$2-K19)))) | P19: =IF(ISNUMBER(O19),ROUND(O19/7,1),O19) | Q19: =IF(J19="","No planificada",IF(G19="Hecho",IF(L19="","Hecha (sin fecha)",IF(L19>K19,"Hecha con atraso","Hecha a tiempo")),IF(Avance!$B$2>K19,"Pendiente atrasada","Pendiente en plazo"))) | R19: HT-03
A20: Sprint 3 | B20: Backend / Firebase | C20: Diseño de datos de las sondas WQS y validación de rango físico | D20: Humberto | E20: 2 | F20: Información técnica de sensores | G20: Hecho | H20: Commit 8d55ccc (25-sep). Base de datos/modelo-datos-sensores.md. [Estimación retroactiva] | I20: Agregada (no planificada) | J20: =IF($I20="Plan original",INDEX('Roadmap Sprints'!$B$2:$B$9,MATCH(IF($A20="Cierre","Semana de cierre",$A20),'Roadmap Sprints'!$A$2:$A$9,0)),"") | K20: =IF($I20="Plan original",INDEX('Roadmap Sprints'!$C$2:$C$9,MATCH(IF($A20="Cierre","Semana de cierre",$A20),'Roadmap Sprints'!$A$2:$A$9,0)),"") | L20: 46290 | M20: =IF(J20="","",NETWORKDAYS(J20,K20)) | N20: =IF(J20="","",IF(L20<>"",IF(L20<J20,0,NETWORKDAYS(J20,L20)),IF(G20="Hecho","",IF(Avance!$B$2<J20,0,NETWORKDAYS(J20,Avance!$B$2))))) | O20: =IF(J20="","n/a",IF(L20<>"",L20-K20,IF(G20="Hecho","s/d",MAX(0,Avance!$B$2-K20)))) | P20: =IF(ISNUMBER(O20),ROUND(O20/7,1),O20) | Q20: =IF(J20="","No planificada",IF(G20="Hecho",IF(L20="","Hecha (sin fecha)",IF(L20>K20,"Hecha con atraso","Hecha a tiempo")),IF(Avance!$B$2>K20,"Pendiente atrasada","Pendiente en plazo"))) | R20: HT-02
